Workbook

Sheet Sheet1
A1: ลำดับ | B1: ทะเบียนรถ | C1: จังหวัด | D1: ยี่ห้อ | E1: รุ่น | F1: สีรถ | G1: วันที่ย้ายรถ | H1: ประเภทรายการ | I1: ลานต้นทาง | J1: ลานปลายทาง | K1: RMO | L1: CMO | M1: สถานะการอนุมัติ(GP) | N1: ชื่อผู้อนุมัติ(GP) | O1: สรุปสถานะอนุมัติ(GP) | P1: ประเภทกรมธรรม์ | Q1: ทุนประกัน | R1: ประมาณการความเสียหาย | S1: มูลค่าซาก(ราคาขาย) | T1: สถานะการขายซากรถยนต์ | U1: วันที่ขาย | V1: วันที่โอนเงิน | W1: วันที่รับเงิน | X1: จำนวนเงินที่ได้รับ | Y1: ชื่อผู้ซื้อซากรถยนต์ | Z1: จ่ายค่าสินไหมจำนวน | AA1: วันที่จ่ายค่าสินไหม | AB1: ชื่อผู้รับเงิน | AC1: หมายเหตุ
A2: 1 | B2: กพ-5389 | C2: สุราษฎร์ธานี | D2: HONDA | E2: CIVIC | H2: ซ่อม | K2: 501-25-71-RMO-01709 | L2: 501-25-71-CMO-01689 | M2: =_xlfn.XLOOKUP(K2,'[1]All เคลมน้ำท่วมรถยนต์'!$C:$C,'[1]All เคลมน้ำท่วมรถยนต์'!$DC:$DC,"") -> เข้าซ่อม | O2: =_xlfn.XLOOKUP(K2,'[1]All เคลมน้ำท่วมรถยนต์'!$C:$C,'[1]All เคลมน้ำท่วมรถยนต์'!$DD:$DD,"") -> เข้าซ่อม | P2: =_xlfn.XLOOKUP(K2,'[1]All เคลมน้ำท่วมรถยนต์'!$C:$C,'[1]All เคลมน้ำท่วมรถยนต์'!$CA:$CA,"") -> ประเภท1 | Q2: =_xlfn.XLOOKUP(K2,'[1]All เคลมน้ำท่วมรถยนต์'!$C:$C,'[1]All เคลมน้ำท่วมรถยนต์'!$BX:$BX,"") -> 200000 | R2: =_xlfn.XLOOKUP(K2,'[1]All เคลมน้ำท่วมรถยนต์'!$C:$C,'[1]All เคลมน้ำท่วมรถยนต์'!$CB:$CB,"") -> 50000 | S2: =_xlfn.XLOOKUP(L2,[2]รายการรถยนต์!$H:$H,[2]รายการรถยนต์!$J:$J,"") | Z2: =_xlfn.XLOOKUP(K2,'[1]All เคลมน้ำท่วมรถยนต์'!$C:$C,'[1]All เคลมน้ำท่วมรถยนต์'!$CS:$CS,"") -> 0 | AA2: =_xlfn.XLOOKUP(K2,'[1]All เคลมน้ำท่วมรถยนต์'!$C:$C,'[1]All เคลมน้ำท่วมรถยนต์'!$CT:$CT,"") | AB2: =_xlfn.XLOOKUP(K2,'[1]All เคลมน้ำท่วมรถยนต์'!$C:$C,'[1]All เคลมน้ำท่วมรถยนต์'!$CV:$CV,"") -> 0
A3: 2 | B3: ขต-7757 | H3: ซ่อม | K3: 501-25-71-RMO-01712 | L3: 501-25-71-CMO-01691 | M3: =_xlfn.XLOOKUP(K3,'[1]All เคลมน้ำท่วมรถยนต์'!$C:$C,'[1]All เคลมน้ำท่วมรถยนต์'!$DC:$DC,"") -> เข้าซ่อม | O3: =_xlfn.XLOOKUP(K3,'[1]All เคลมน้ำท่วมรถยนต์'!$C:$C,'[1]All เคลมน้ำท่วมรถยนต์'!$DD:$DD,"") -> เข้าซ่อม | P3: =_xlfn.XLOOKUP(K3,'[1]All เคลมน้ำท่วมรถยนต์'!$C:$C,'[1]All เคลมน้ำท่วมรถยนต์'!$CA:$CA,"") -> ประเภท1 | Q3: =_xlfn.XLOOKUP(K3,'[1]All เคลมน้ำท่วมรถยนต์'!$C:$C,'[1]All เคลมน้ำท่วมรถยนต์'!$BX:$BX,"") -> 1200000 | R3: =_xlfn.XLOOKUP(K3,'[1]All เคลมน้ำท่วมรถยนต์'!$C:$C,'[1]All เคลมน้ำท่วมรถยนต์'!$CB:$CB,"") -> 500000 | S3: =_xlfn.XLOOKUP(L3,[2]รายการรถยนต์!$H:$H,[2]รายการรถยนต์!$J:$J,"") | Z3: =_xlfn.XLOOKUP(K3,'[1]All เคลมน้ำท่วมรถยนต์'!$C:$C,'[1]All เคลมน้ำท่วมรถยนต์'!$CS:$CS,"") -> 0 | AA3: =_xlfn.XLOOKUP(K3,'[1]All เคลมน้ำท่วมรถยนต์'!$C:$C,'[1]All เคลมน้ำท่วมรถยนต์'!$CT:$CT,"") | AB3: =_xlfn.XLOOKUP(K3,'[1]All เคลมน้ำท่วมรถยนต์'!$C:$C,'[1]All เคลมน้ำท่วมรถยนต์'!$CV:$CV,"") -> 0
A4: 3 | B4: 8กท-9338 | F4: ขาว | G4: 46002.435 | I4: ลาน7-ธรรมกาย | K4: 502-25-71-RMO-04031 | L4: 502-25-71-CMO-03975 | M4: =_xlfn.XLOOKUP(K4,'[1]All เคลมน้ำท่วมรถยนต์'!$C:$C,'[1]All เคลมน้ำท่วมรถยนต์'!$DC:$DC,"") -> อนุมัติคืนทุน | O4: =_xlfn.XLOOKUP(K4,'[1]All เคลมน้ำท่วมรถยนต์'!$C:$C,'[1]All เคลมน้ำท่วมรถยนต์'!$DD:$DD,"") -> จ่ายแล้ว/ ยกเลิก | P4: =_xlfn.XLOOKUP(K4,'[1]All เคลมน้ำท่วมรถยนต์'!$C:$C,'[1]All เคลมน้ำท่วมรถยนต์'!$CA:$CA,"") -> ประเภท1 | Q4: =_xlfn.XLOOKUP(K4,'[1]All เคลมน้ำท่วมรถยนต์'!$C:$C,'[1]All เคลมน้ำท่วมรถยนต์'!$BX:$BX,"") -> 810000 | R4: =_xlfn.XLOOKUP(K4,'[1]All เคลมน้ำท่วมรถยนต์'!$C:$C,'[1]All เคลมน้ำท่วมรถยนต์'!$CB:$CB,"") -> 300000 | S4: =_xlfn.XLOOKUP(L4,[2]รายการรถยนต์!$H:$H,[2]รายการรถยนต์!$J:$J,"") | Z4: =_xlfn.XLOOKUP(K4,'[1]All เคลมน้ำท่วมรถยนต์'!$C:$C,'[1]All เคลมน้ำท่วมรถยนต์'!$CS:$CS,"") -> 810000 | AA4: =_xlfn.XLOOKUP(K4,'[1]All เคลมน้ำท่วมรถยนต์'!$C:$C,'[1]All เคลมน้ำท่วมรถยนต์'!$CT:$CT,"") -> 46015 | AB4: =_xlfn.XLOOKUP(K4,'[1]All เคลมน้ำท่วมรถยนต์'!$C:$C,'[1]All เคลมน้ำท่วมรถยนต์'!$CV:$CV,"") -> คุณ นันท์นภัส ชูเมือง
A5: 4 | B5: งค-8342 | C5: สงขลา | D5: MAZDA | E5: 2 | K5: 502-25-71-RMO-04038 | L5: 502-25-71-CMO-03965 | M5: =_xlfn.XLOOKUP(K5,'[1]All เคลมน้ำท่วมรถยนต์'!$C:$C,'[1]All เคลมน้ำท่วมรถยนต์'!$DC:$DC,"") | O5: =_xlfn.XLOOKUP(K5,'[1]All เคลมน้ำท่วมรถยนต์'!$C:$C,'[1]All เคลมน้ำท่วมรถยนต์'!$DD:$DD,"") -> จ่ายแล้ว/ ยกเลิก | P5: =_xlfn.XLOOKUP(K5,'[1]All เคลมน้ำท่วมรถยนต์'!$C:$C,'[1]All เคลมน้ำท่วมรถยนต์'!$CA:$CA,"") -> ประเภท1 | Q5: =_xlfn.XLOOKUP(K5,'[1]All เคลมน้ำท่วมรถยนต์'!$C:$C,'[1]All เคลมน้ำท่วมรถยนต์'!$BX:$BX,"") -> 360000 | R5: =_xlfn.XLOOKUP(K5,'[1]All เคลมน้ำท่วมรถยนต์'!$C:$C,'[1]All เคลมน้ำท่วมรถยนต์'!$CB:$CB,"") -> 0 ยกเลิกเคลมไม่เสียหาย | S5: =_xlfn.XLOOKUP(L5,[2]รายการรถยนต์!$H:$H,[2]รายการรถยนต์!$J:$J,"") | Z5: =_xlfn.XLOOKUP(K5,'[1]All เคลมน้ำท่วมรถยนต์'!$C:$C,'[1]All เคลมน้ำท่วมรถยนต์'!$CS:$CS,"") -> 0 | AA5: =_xlfn.XLOOKUP(K5,'[1]All เคลมน้ำท่วมรถยนต์'!$C:$C,'[1]All เคลมน้ำท่วมรถยนต์'!$CT:$CT,"") | AB5: =_xlfn.XLOOKUP(K5,'[1]All เคลมน้ำท่วมรถยนต์'!$C:$C,'[1]All เคลมน้ำท่วมรถยนต์'!$CV:$CV,"") -> 0
A6: 5 | B6: 9กธ-1147 | H6: ซ่อม | K6: 502-25-71-RMO-04040 | L6: 502-25-71-CMO-03967 | M6: =_xlfn.XLOOKUP(K6,'[1]All เคลมน้ำท่วมรถยนต์'!$C:$C,'[1]All เคลมน้ำท่วมรถยนต์'!$DC:$DC,"") -> เข้าซ่อม | O6: =_xlfn.XLOOKUP(K6,'[1]All เคลมน้ำท่วมรถยนต์'!$C:$C,'[1]All เคลมน้ำท่วมรถยนต์'!$DD:$DD,"") -> เข้าซ่อม | P6: =_xlfn.XLOOKUP(K6,'[1]All เคลมน้ำท่วมรถยนต์'!$C:$C,'[1]All เคลมน้ำท่วมรถยนต์'!$CA:$CA,"") -> ประเภท1 | Q6: =_xlfn.XLOOKUP(K6,'[1]All เคลมน้ำท่วมรถยนต์'!$C:$C,'[1]All เคลมน้ำท่วมรถยนต์'!$BX:$BX,"") -> 590000 | R6: =_xlfn.XLOOKUP(K6,'[1]All เคลมน้ำท่วมรถยนต์'!$C:$C,'[1]All เคลมน้ำท่วมรถยนต์'!$CB:$CB,"") -> 10000 | S6: =_xlfn.XLOOKUP(L6,[2]รายการรถยนต์!$H:$H,[2]รายการรถยนต์!$J:$J,"") | Z6: =_xlfn.XLOOKUP(K6,'[1]All เคลมน้ำท่วมรถยนต์'!$C:$C,'[1]All เคลมน้ำท่วมรถยนต์'!$CS:$CS,"") -> 0 | AA6: =_xlfn.XLOOKUP(K6,'[1]All เคลมน้ำท่วมรถยนต์'!$C:$C,'[1]All เคลมน้ำท่วมรถยนต์'!$CT:$CT,"") | AB6: =_xlfn.XLOOKUP(K6,'[1]All เคลมน้ำท่วมรถยนต์'!$C:$C,'[1]All เคลมน้ำท่วมรถยนต์'!$CV:$CV,"") -> 0
A7: 6 | K7: 502-25-71-RMO-04041 | L7: 502-25-71-CMO-03968 | M7: =_xlfn.XLOOKUP(K7,'[1]All เคลมน้ำท่วมรถยนต์'!$C:$C,'[1]All เคลมน้ำท่วมรถยนต์'!$DC:$DC,"") -> เข้าซ่อม | O7: =_xlfn.XLOOKUP(K7,'[1]All เคลมน้ำท่วมรถยนต์'!$C:$C,'[1]All เคลมน้ำท่วมรถยนต์'!$DD:$DD,"") -> เข้าซ่อม | P7: =_xlfn.XLOOKUP(K7,'[1]All เคลมน้ำท่วมรถยนต์'!$C:$C,'[1]All เคลมน้ำท่วมรถยนต์'!$CA:$CA,"") -> ประเภท1 | Q7: =_xlfn.XLOOKUP(K7,'[1]All เคลมน้ำท่วมรถยนต์'!$C:$C,'[1]All เคลมน้ำท่วมรถยนต์'!$BX:$BX,"") -> 140000 | R7: =_xlfn.XLOOKUP(K7,'[1]All เคลมน้ำท่วมรถยนต์'!$C:$C,'[1]All เคลมน้ำท่วมรถยนต์'!$CB:$CB,"") -> 20000 | S7: =_xlfn.XLOOKUP(L7,[2]รายการรถยนต์!$H:$H,[2]รายการรถยนต์!$J:$J,"") | Z7: =_xlfn.XLOOKUP(K7,'[1]All เคลมน้ำท่วมรถยนต์'!$C:$C,'[1]All เคลมน้ำท่วมรถยนต์'!$CS:$CS,"") -> 0 | AA7: =_xlfn.XLOOKUP(K7,'[1]All เคลมน้ำท่วมรถยนต์'!$C:$C,'[1]All เคลมน้ำท่วมรถยนต์'!$CT:$CT,"") | AB7: =_xlfn.XLOOKUP(K7,'[1]All เคลมน้ำท่วมรถยนต์'!$C:$C,'[1]All เคลมน้ำท่วมรถยนต์'!$CV:$CV,"") -> 0
A8: 7 | B8: ขร-9016 | H8: ซ่อม | K8: 502-25-71-RMO-04043 | L8: 502-25-71-CMO-03969 | M8: =_xlfn.XLOOKUP(K8,'[1]All เคลมน้ำท่วมรถยนต์'!$C:$C,'[1]All เคลมน้ำท่วมรถยนต์'!$DC:$DC,"") -> เข้าซ่อม | O8: =_xlfn.XLOOKUP(K8,'[1]All เคลมน้ำท่วมรถยนต์'!$C:$C,'[1]All เคลมน้ำท่วมรถยนต์'!$DD:$DD,"") -> เข้าซ่อม | P8: =_xlfn.XLOOKUP(K8,'[1]All เคลมน้ำท่วมรถยนต์'!$C:$C,'[1]All เคลมน้ำท่วมรถยนต์'!$CA:$CA,"") -> ประเภท1 | Q8: =_xlfn.XLOOKUP(K8,'[1]All เคลมน้ำท่วมรถยนต์'!$C:$C,'[1]All เคลมน้ำท่วมรถยนต์'!$BX:$BX,"") -> 270000 | R8: =_xlfn.XLOOKUP(K8,'[1]All เคลมน้ำท่วมรถยนต์'!$C:$C,'[1]All เคลมน้ำท่วมรถยนต์'!$CB:$CB,"") -> 50000 | S8: =_xlfn.XLOOKUP(L8,[2]รายการรถยนต์!$H:$H,[2]รายการรถยนต์!$J:$J,"") | Z8: =_xlfn.XLOOKUP(K8,'[1]All เคลมน้ำท่วมรถยนต์'!$C:$C,'[1]All เคลมน้ำท่วมรถยนต์'!$CS:$CS,"") -> 0 | AA8: =_xlfn.XLOOKUP(K8,'[1]All เคลมน้ำท่วมรถยนต์'!$C:$C,'[1]All เคลมน้ำท่วมรถยนต์'!$CT:$CT,"") | AB8: =_xlfn.XLOOKUP(K8,'[1]All เคลมน้ำท่วมรถยนต์'!$C:$C,'[1]All เคลมน้ำท่วมรถยนต์'!$CV:$CV,"") -> 0
A9: 8 | B9: กม-2540 | C9: ภูเก็ต | D9: NISSAN | E9: MARCH | K9: 502-25-71-RMO-04044 | L9: 502-25-71-CMO-03991 | M9: =_xlfn.XLOOKUP(K9,'[1]All เคลมน้ำท่วมรถยนต์'!$C:$C,'[1]All เคลมน้ำท่วมรถยนต์'!$DC:$DC,"") -> อนุมัติคืนทุน | O9: =_xlfn.XLOOKUP(K9,'[1]All เคลมน้ำท่วมรถยนต์'!$C:$C,'[1]All เคลมน้ำท่วมรถยนต์'!$DD:$DD,"") -> จ่ายแล้ว/ ยกเลิก | P9: =_xlfn.XLOOKUP(K9,'[1]All เคลมน้ำท่วมรถยนต์'!$C:$C,'[1]All เคลมน้ำท่วมรถยนต์'!$CA:$CA,"") -> ประเภท1 | Q9: =_xlfn.XLOOKUP(K9,'[1]All เคลมน้ำท่วมรถยนต์'!$C:$C,'[1]All เคลมน้ำท่วมรถยนต์'!$BX:$BX,"") -> 140000 | R9: =_xlfn.XLOOKUP(K9,'[1]All เคลมน้ำท่วมรถยนต์'!$C:$C,'[1]All เคลมน้ำท่วมรถยนต์'!$CB:$CB,"") -> 140000 | S9: =_xlfn.XLOOKUP(L9,[2]รายการรถยนต์!$H:$H,[2]รายการรถยนต์!$J:$J,"") | Z9: =_xlfn.XLOOKUP(K9,'[1]All เคลมน้ำท่วมรถยนต์'!$C:$C,'[1]All เคลมน้ำท่วมรถยนต์'!$CS:$CS,"") -> 140000 | AA9: =_xlfn.XLOOKUP(K9,'[1]All เคลมน้ำท่วมรถยนต์'!$C:$C,'[1]All เคลมน้ำท่วมรถยนต์'!$CT:$CT,"") -> 46037 | AB9: =_xlfn.XLOOKUP(K9,'[1]All เคลมน้ำท่วมรถยนต์'!$C:$C,'[1]All เคลมน้ำท่วมรถยนต์'!$CV:$CV,"") -> นางสาว ปฏิมาพร พรหมรัตน์
A10: 9 | B10: 4ขห-5631 | K10: 502-25-71-RMO-04046 | L10: 502-25-71-CMO-03993 | M10: =_xlfn.XLOOKUP(K10,'[1]All เคลมน้ำท่วมรถยนต์'!$C:$C,'[1]All เคลมน้ำท่วมรถยนต์'!$DC:$DC,"") -> อนุมัติคืนทุน | O10: =_xlfn.XLOOKUP(K10,'[1]All เคลมน้ำท่วมรถยนต์'!$C:$C,'[1]All เคลมน้ำท่วมรถยนต์'!$DD:$DD,"") -> จ่ายแล้ว/ ยกเลิก | P10: =_xlfn.XLOOKUP(K10,'[1]All เคลมน้ำท่วมรถยนต์'!$C:$C,'[1]All เคลมน้ำท่วมรถยนต์'!$CA:$CA,"") -> ประเภท1 | Q10: =_xlfn.XLOOKUP(K10,'[1]All เคลมน้ำท่วมรถยนต์'!$C:$C,'[1]All เคลมน้ำท่วมรถยนต์'!$BX:$BX,"") -> 1200000 | R10: =_xlfn.XLOOKUP(K10,'[1]All เคลมน้ำท่วมรถยนต์'!$C:$C,'[1]All เคลมน้ำท่วมรถยนต์'!$CB:$CB,"") -> 1200000 | S10: =_xlfn.XLOOKUP(L10,[2]รายการรถยนต์!$H:$H,[2]รายการรถยนต์!$J:$J,"") | Z10: =_xlfn.XLOOKUP(K10,'[1]All เคลมน้ำท่วมรถยนต์'!$C:$C,'[1]All เคลมน้ำท่วมรถยนต์'!$CS:$CS,"") -> 1200000 | AA10: =_xlfn.XLOOKUP(K10,'[1]All เคลมน้ำท่วมรถยนต์'!$C:$C,'[1]All เคลมน้ำท่วมรถยนต์'!$CT:$CT,"") -> 46028 | AB10: =_xlfn.XLOOKUP(K10,'[1]All เคลมน้ำท่วมรถยนต์'!$C:$C,'[1]All เคลมน้ำท่วมรถยนต์'!$CV:$CV,"") -> ธนาคารกรุงศรีอยุธยา จำกัด (มหาชน)
A11: 10 | B11: 3ขผ-2609 | K11: 502-25-71-RMO-04047 | L11: 502-25-71-CMO-04008 | M11: =_xlfn.XLOOKUP(K11,'[1]All เคลมน้ำท่วมรถยนต์'!$C:$C,'[1]All เคลมน้ำท่วมรถยนต์'!$DC:$DC,"") -> อนุมัติคืนทุน | O11: =_xlfn.XLOOKUP(K11,'[1]All เคลมน้ำท่วมรถยนต์'!$C:$C,'[1]All เคลมน้ำท่วมรถยนต์'!$DD:$DD,"") -> จ่ายแล้ว/ ยกเลิก | P11: =_xlfn.XLOOKUP(K11,'[1]All เคลมน้ำท่วมรถยนต์'!$C:$C,'[1]All เคลมน้ำท่วมรถยนต์'!$CA:$CA,"") -> ประเภท1 | Q11: =_xlfn.XLOOKUP(K11,'[1]All เคลมน้ำท่วมรถยนต์'!$C:$C,'[1]All เคลมน้ำท่วมรถยนต์'!$BX:$BX,"") -> 1750000 | R11: =_xlfn.XLOOKUP(K11,'[1]All เคลมน้ำท่วมรถยนต์'!$C:$C,'[1]All เคลมน้ำท่วมรถยนต์'!$CB:$CB,"") -> 1750000 | S11: =_xlfn.XLOOKUP(L11,[2]รายการรถยนต์!$H:$H,[2]รายการรถยนต์!$J:$J,"") | Z11: =_xlfn.XLOOKUP(K11,'[1]All เคลมน้ำท่วมรถยนต์'!$C:$C,'[1]All เคลมน้ำท่วมรถยนต์'!$CS:$CS,"") -> 1750000 | AA11: =_xlfn.XLOOKUP(K11,'[1]All เคลมน้ำท่วมรถยนต์'!$C:$C,'[1]All เคลมน้ำท่วมรถยนต์'!$CT:$CT,"") -> 46042 | AB11: =_xlfn.XLOOKUP(K11,'[1]All เคลมน้ำท่วมรถยนต์'!$C:$C,'[1]All เคลมน้ำท่วมรถยนต์'!$CV:$CV,"") -> บริษัท ตะวันออกพาณิชย์ลีสซิ่ง จำกัด(มหาชน)
A12: 11 | B12: งค-5368 | C12: สงขลา | D12: NISSAN | E12: ALMERA 1.0 | K12: 502-25-71-RMO-04048 | L12: 502-25-71-CMO-04003 | M12: =_xlfn.XLOOKUP(K12,'[1]All เคลมน้ำท่วมรถยนต์'!$C:$C,'[1]All เคลมน้ำท่วมรถยนต์'!$DC:$DC,"") | O12: =_xlfn.XLOOKUP(K12,'[1]All เคลมน้ำท่วมรถยนต์'!$C:$C,'[1]All เคลมน้ำท่วมรถยนต์'!$DD:$DD,"") -> จ่ายแล้ว/ ยกเลิก | P12: =_xlfn.XLOOKUP(K12,'[1]All เคลมน้ำท่วมรถยนต์'!$C:$C,'[1]All เคลมน้ำท่วมรถยนต์'!$CA:$CA,"") -> ประเภท2+ | Q12: =_xlfn.XLOOKUP(K12,'[1]All เคลมน้ำท่วมรถยนต์'!$C:$C,'[1]All เคลมน้ำท่วมรถยนต์'!$BX:$BX,"") -> 100000 | R12: =_xlfn.XLOOKUP(K12,'[1]All เคลมน้ำท่วมรถยนต์'!$C:$C,'[1]All เคลมน้ำท่วมรถยนต์'!$CB:$CB,"") -> 0 ไม่คุ้มครองภัยน้ำท่วม | S12: =_xlfn.XLOOKUP(L12,[2]รายการรถยนต์!$H:$H,[2]รายการรถยนต์!$J:$J,"") | Z12: =_xlfn.XLOOKUP(K12,'[1]All เคลมน้ำท่วมรถยนต์'!$C:$C,'[1]All เคลมน้ำท่วมรถยนต์'!$CS:$CS,"") -> 0 | AA12: =_xlfn.XLOOKUP(K12,'[1]All เคลมน้ำท่วมรถยนต์'!$C:$C,'[1]All เคลมน้ำท่วมรถยนต์'!$CT:$CT,"") -> ยกเลิกเคลม | AB12: =_xlfn.XLOOKUP(K12,'[1]All เคลมน้ำท่วมรถยนต์'!$C:$C,'[1]All เคลมน้ำท่วมรถยนต์'!$CV:$CV,"") -> 0
A13: 12 | B13: ขว-8299 | C13: สงขลา | D13: HONDA | E13: HR-V | F13: แดง | G13: 46045 | H13: ย้ายลาน | I13: ลาน3-สะพานสูงเทคโน(Motto) | J13: ลาน8-ไฟร์มเครสต์ | K13: 502-25-71-RMO-04049 | L13: 502-25-71-CMO-04010 | M13: =_xlfn.XLOOKUP(K13,'[1]All เคลมน้ำท่วมรถยนต์'!$C:$C,'[1]All เคลมน้ำท่วมรถยนต์'!$DC:$DC,"") -> อนุมัติคืนทุน | O13: =_xlfn.XLOOKUP(K13,'[1]All เคลมน้ำท่วมรถยนต์'!$C:$C,'[1]All เคลมน้ำท่วมรถยนต์'!$DD:$DD,"") -> จ่ายแล้ว/ ยกเลิก | P13: =_xlfn.XLOOKUP(K13,'[1]All เคลมน้ำท่วมรถยนต์'!$C:$C,'[1]All เคลมน้ำท่วมรถยนต์'!$CA:$CA,"") -> ประเภท1 | Q13: =_xlfn.XLOOKUP(K13,'[1]All เคลมน้ำท่วมรถยนต์'!$C:$C,'[1]All เคลมน้ำท่วมรถยนต์'!$BX:$BX,"") -> 480000 | R13: =_xlfn.XLOOKUP(K13,'[1]All เคลมน้ำท่วมรถยนต์'!$C:$C,'[1]All เคลมน้ำท่วมรถยนต์'!$CB:$CB,"") -> 480000 | S13: =_xlfn.XLOOKUP(L13,[2]รายการรถยนต์!$H:$H,[2]รายการรถยนต์!$J:$J,"") -> 182400 | Z13: =_xlfn.XLOOKUP(K13,'[1]All เคลมน้ำท่วมรถยนต์'!$C:$C,'[1]All เคลมน้ำท่วมรถยนต์'!$CS:$CS,"") -> 480000 | AA13: =_xlfn.XLOOKUP(K13,'[1]All เคลมน้ำท่วมรถยนต์'!$C:$C,'[1]All เคลมน้ำท่วมรถยนต์'!$CT:$CT,"") -> 46015 | AB13: =_xlfn.XLOOKUP(K13,'[1]All เคลมน้ำท่วมรถยนต์'!$C:$C,'[1]All เคลมน้ำท่วมรถยนต์'!$CV:$CV,"") -> นางสาว ธนภรณ์ เพ็ชรชะระ
A14: 13 | B14: กอ-8811 | C14: สงขลา | D14: HONDA | E14: CR-V | F14: ดำ | G14: 46045 | H14: ย้ายลาน | I14: ลาน3-สะพานสูงเทคโน(Motto) | J14: ลาน8-ไฟร์มเครสต์ | K14: 502-25-71-RMO-04050 | L14: 502-25-71-CMO-04009 | M14: =_xlfn.XLOOKUP(K14,'[1]All เคลมน้ำท่วมรถยนต์'!$C:$C,'[1]All เคลมน้ำท่วมรถยนต์'!$DC:$DC,"") -> อนุมัติคืนทุน | O14: =_xlfn.XLOOKUP(K14,'[1]All เคลมน้ำท่วมรถยนต์'!$C:$C,'[1]All เคลมน้ำท่วมรถยนต์'!$DD:$DD,"") -> จ่ายแล้ว/ ยกเลิก | P14: =_xlfn.XLOOKUP(K14,'[1]All เคลมน้ำท่วมรถยนต์'!$C:$C,'[1]All เคลมน้ำท่วมรถยนต์'!$CA:$CA,"") -> ประเภท1 | Q14: =_xlfn.XLOOKUP(K14,'[1]All เคลมน้ำท่วมรถยนต์'!$C:$C,'[1]All เคลมน้ำท่วมรถยนต์'!$BX:$BX,"") -> 270000 | R14: =_xlfn.XLOOKUP(K14,'[1]All เคลมน้ำท่วมรถยนต์'!$C:$C,'[1]All เคลมน้ำท่วมรถยนต์'!$CB:$CB,"") -> 270000 | S14: =_xlfn.XLOOKUP(L14,[2]รายการรถยนต์!$H:$H,[2]รายการรถยนต์!$J:$J,"") -> 102600 | Z14: =_xlfn.XLOOKUP(K14,'[1]All เคลมน้ำท่วมรถยนต์'!$C:$C,'[1]All เคลมน้ำท่วมรถยนต์'!$CS:$CS,"") -> 270000 | AA14: =_xlfn.XLOOKUP(K14,'[1]All เคลมน้ำท่วมรถยนต์'!$C:$C,'[1]All เคลมน้ำท่วมรถยนต์'!$CT:$CT,"") -> 46015 | AB14: =_xlfn.XLOOKUP(K14,'[1]All เคลมน้ำท่วมรถยนต์'!$C:$C,'[1]All เคลมน้ำท่วมรถยนต์'!$CV:$CV,"") -> นางสาว จรรยา จันทร์ปาน
A15: 14 | B15: กร-9117 | C15: สงขลา | D15: HONDA | E15: CIVIC | F15: ดำ | G15: 46045 | H15: ย้ายลาน | I15: ลาน3-สะพานสูงเทคโน(Motto) | J15: ลาน8-ไฟร์มเครสต์ | K15: 502-25-71-RMO-04051 | L15: 502-25-71-CMO-03992 | M15: =_xlfn.XLOOKUP(K15,'[1]All เคลมน้ำท่วมรถยนต์'!$C:$C,'[1]All เคลมน้ำท่วมรถยนต์'!$DC:$DC,"") -> อนุมัติคืนทุน | O15: =_xlfn.XLOOKUP(K15,'[1]All เคลมน้ำท่วมรถยนต์'!$C:$C,'[1]All เคลมน้ำท่วมรถยนต์'!$DD:$DD,"") -> จ่ายแล้ว/ ยกเลิก | P15: =_xlfn.XLOOKUP(K15,'[1]All เคลมน้ำท่วมรถยนต์'!$C:$C,'[1]All เคลมน้ำท่วมรถยนต์'!$CA:$CA,"") -> ประเภท1 | Q15: =_xlfn.XLOOKUP(K15,'[1]All เคลมน้ำท่วมรถยนต์'!$C:$C,'[1]All เคลมน้ำท่วมรถยนต์'!$BX:$BX,"") -> 200000 | R15: =_xlfn.XLOOKUP(K15,'[1]All เคลมน้ำท่วมรถยนต์'!$C:$C,'[1]All เคลมน้ำท่วมรถยนต์'!$CB:$CB,"") -> 11649 | S15: =_xlfn.XLOOKUP(L15,[2]รายการรถยนต์!$H:$H,[2]รายการรถยนต์!$J:$J,"") -> 76000 | Z15: =_xlfn.XLOOKUP(K15,'[1]All เคลมน้ำท่วมรถยนต์'!$C:$C,'[1]All เคลมน้ำท่วมรถยนต์'!$CS:$CS,"") -> 200000 | AA15: =_xlfn.XLOOKUP(K15,'[1]All เคลมน้ำท่วมรถยนต์'!$C:$C,'[1]All เคลมน้ำท่วมรถยนต์'!$CT:$CT,"") -> 46030 | AB15: =_xlfn.XLOOKUP(K15,'[1]All เคลมน้ำท่วมรถยนต์'!$C:$C,'[1]All เคลมน้ำท่วมรถยนต์'!$CV:$CV,"") -> นางสาว ณัฐวดี กาฬสินธุ์
A16: 15 | B16: งข-6069 | C16: สงขลา | D16: TOYOTA | E16: YARIS 1.2 | F16: ขาว | G16: 46045 | H16: ย้ายลาน | I16: ลาน1-ช่องเขา | J16: ลาน8-ไฟร์มเครสต์ | K16: 502-25-71-RMO-04052 | L16: 502-25-71-CMO-04011 | M16: =_xlfn.XLOOKUP(K16,'[1]All เคลมน้ำท่วมรถยนต์'!$C:$C,'[1]All เคลมน้ำท่วมรถยนต์'!$DC:$DC,"") -> อนุมัติคืนทุน | O16: =_xlfn.XLOOKUP(K16,'[1]All เคลมน้ำท่วมรถยนต์'!$C:$C,'[1]All เคลมน้ำท่วมรถยนต์'!$DD:$DD,"") -> leasing | P16: =_xlfn.XLOOKUP(K16,'[1]All เคลมน้ำท่วมรถยนต์'!$C:$C,'[1]All เคลมน้ำท่วมรถยนต์'!$CA:$CA,"") -> ประเภท1 | Q16: =_xlfn.XLOOKUP(K16,'[1]All เคลมน้ำท่วมรถยนต์'!$C:$C,'[1]All เคลมน้ำท่วมรถยนต์'!$BX:$BX,"") -> 320000 | R16: =_xlfn.XLOOKUP(K16,'[1]All เคลมน้ำท่วมรถยนต์'!$C:$C,'[1]All เคลมน้ำท่วมรถยนต์'!$CB:$CB,"") -> 320000 | S16: =_xlfn.XLOOKUP(L16,[2]รายการรถยนต์!$H:$H,[2]รายการรถยนต์!$J:$J,"") -> 121600 | Z16: =_xlfn.XLOOKUP(K16,'[1]All เคลมน้ำท่วมรถยนต์'!$C:$C,'[1]All เคลมน้ำท่วมรถยนต์'!$CS:$CS,"") -> 0 | AA16: =_xlfn.XLOOKUP(K16,'[1]All เคลมน้ำท่วมรถยนต์'!$C:$C,'[1]All เคลมน้ำท่วมรถยนต์'!$CT:$CT,"") | AB16: =_xlfn.XLOOKUP(K16,'[1]All เคลมน้ำท่วมรถยนต์'!$C:$C,'[1]All เคลมน้ำท่วมรถยนต์'!$CV:$CV,"") -> 0
A17: 16 | B17: งฉ-5045 | C17: สงขลา | D17: MERCEDES-BENZ | E17: GLA200 | H17: ซ่อม | K17: 502-25-71-RMO-04053 | L17: 502-25-71-CMO-04007 | M17: =_xlfn.XLOOKUP(K17,'[1]All เคลมน้ำท่วมรถยนต์'!$C:$C,'[1]All เคลมน้ำท่วมรถยนต์'!$DC:$DC,"") -> อนุมัติเหมาซ่อม | O17: =_xlfn.XLOOKUP(K17,'[1]All เคลมน้ำท่วมรถยนต์'!$C:$C,'[1]All เคลมน้ำท่วมรถยนต์'!$DD:$DD,"") -> จ่ายแล้ว/ ยกเลิก | P17: =_xlfn.XLOOKUP(K17,'[1]All เคลมน้ำท่วมรถยนต์'!$C:$C,'[1]All เคลมน้ำท่วมรถยนต์'!$CA:$CA,"") -> ประเภท1 | Q17: =_xlfn.XLOOKUP(K17,'[1]All เคลมน้ำท่วมรถยนต์'!$C:$C,'[1]All เคลมน้ำท่วมรถยนต์'!$BX:$BX,"") -> 560000 | R17: =_xlfn.XLOOKUP(K17,'[1]All เคลมน้ำท่วมรถยนต์'!$C:$C,'[1]All เคลมน้ำท่วมรถยนต์'!$CB:$CB,"") -> 100000 | S17: =_xlfn.XLOOKUP(L17,[2]รายการรถยนต์!$H:$H,[2]รายการรถยนต์!$J:$J,"") | Z17: =_xlfn.XLOOKUP(K17,'[1]All เคลมน้ำท่วมรถยนต์'!$C:$C,'[1]All เคลมน้ำท่วมรถยนต์'!$CS:$CS,"") -> 120000 | AA17: =_xlfn.XLOOKUP(K17,'[1]All เคลมน้ำท่วมรถยนต์'!$C:$C,'[1]All เคลมน้ำท่วมรถยนต์'!$CT:$CT,"") -> 46029 | AB17: =_xlfn.XLOOKUP(K17,'[1]All เคลมน้ำท่วมรถยนต์'!$C:$C,'[1]All เคลมน้ำท่วมรถยนต์'!$CV:$CV,"") -> นางสาว สุรัตนวดี ชูแก้ว
A18: 17 | B18: กท-8045 | C18: สงขลา | D18: TOYOTA | E18: VIOS | K18: 502-25-71-RMO-04054 | L18: 502-25-71-CMO-03990 | M18: =_xlfn.XLOOKUP(K18,'[1]All เคลมน้ำท่วมรถยนต์'!$C:$C,'[1]All เคลมน้ำท่วมรถยนต์'!$DC:$DC,"") | O18: =_xlfn.XLOOKUP(K18,'[1]All เคลมน้ำท่วมรถยนต์'!$C:$C,'[1]All เคลมน้ำท่วมรถยนต์'!$DD:$DD,"") -> จ่ายแล้ว/ ยกเลิก | P18: =_xlfn.XLOOKUP(K18,'[1]All เคลมน้ำท่วมรถยนต์'!$C:$C,'[1]All เคลมน้ำท่วมรถยนต์'!$CA:$CA,"") -> ประเภท2+ | Q18: =_xlfn.XLOOKUP(K18,'[1]All เคลมน้ำท่วมรถยนต์'!$C:$C,'[1]All เคลมน้ำท่วมรถยนต์'!$BX:$BX,"") -> 100000 | R18: =_xlfn.XLOOKUP(K18,'[1]All เคลมน้ำท่วมรถยนต์'!$C:$C,'[1]All เคลมน้ำท่วมรถยนต์'!$CB:$CB,"") -> 0 ไม่คุ้มครองภัยน้ำท่วม | S18: =_xlfn.XLOOKUP(L18,[2]รายการรถยนต์!$H:$H,[2]รายการรถยนต์!$J:$J,"") | Z18: =_xlfn.XLOOKUP(K18,'[1]All เคลมน้ำท่วมรถยนต์'!$C:$C,'[1]All เคลมน้ำท่วมรถยนต์'!$CS:$CS,"") -> 0 | AA18: =_xlfn.XLOOKUP(K18,'[1]All เคลมน้ำท่วมรถยนต์'!$C:$C,'[1]All เคลมน้ำท่วมรถยนต์'!$CT:$CT,"") -> ยกเลิกเคลม | AB18: =_xlfn.XLOOKUP(K18,'[1]All เคลมน้ำท่วมรถยนต์'!$C:$C,'[1]All เคลมน้ำท่วมรถยนต์'!$CV:$CV,"") -> 0
A19: 18 | B19: 3ขศ-5375 | K19: 502-25-71-RMO-04055 | L19: 502-25-71-CMO-03988 | M19: =_xlfn.XLOOKUP(K19,'[1]All เคลมน้ำท่วมรถยนต์'!$C:$C,'[1]All เคลมน้ำท่วมรถยนต์'!$DC:$DC,"") -> อนุมัติคืนทุน | O19: =_xlfn.XLOOKUP(K19,'[1]All เคลมน้ำท่วมรถยนต์'!$C:$C,'[1]All เคลมน้ำท่วมรถยนต์'!$DD:$DD,"") -> leasing | P19: =_xlfn.XLOOKUP(K19,'[1]All เคลมน้ำท่วมรถยนต์'!$C:$C,'[1]All เคลมน้ำท่วมรถยนต์'!$CA:$CA,"") -> ประเภท1 | Q19: =_xlfn.XLOOKUP(K19,'[1]All เคลมน้ำท่วมรถยนต์'!$C:$C,'[1]All เคลมน้ำท่วมรถยนต์'!$BX:$BX,"") -> 850000 | R19: =_xlfn.XLOOKUP(K19,'[1]All เคลมน้ำท่วมรถยนต์'!$C:$C,'[1]All เคลมน้ำท่วมรถยนต์'!$CB:$CB,"") -> 850000 | S19: =_xlfn.XLOOKUP(L19,[2]รายการรถยนต์!$H:$H,[2]รายการรถยนต์!$J:$J,"") -> 323000 | Z19: =_xlfn.XLOOKUP(K19,'[1]All เคลมน้ำท่วมรถยนต์'!$C:$C,'[1]All เคลมน้ำท่วมรถยนต์'!$CS:$CS,"") -> 0 | AA19: =_xlfn.XLOOKUP(K19,'[1]All เคลมน้ำท่วมรถยนต์'!$C:$C,'[1]All เคลมน้ำท่วมรถยนต์'!$CT:$CT,"") | AB19: =_xlfn.XLOOKUP(K19,'[1]All เคลมน้ำท่วมรถยนต์'!$C:$C,'[1]All เคลมน้ำท่วมรถยนต์'!$CV:$CV,"") -> 0
A20: 19 | B20: งท-6364 | C20: สงขลา | D20: TOYOTA | E20: COROLLA CROSS | F20: ขาว | G20: 46002.419 | I20: ลาน1-ช่องเขา | K20: 502-25-71-RMO-04057 | L20: 502-25-71-CMO-04012 | M20: =_xlfn.XLOOKUP(K20,'[1]All เคลมน้ำท่วมรถยนต์'!$C:$C,'[1]All เคลมน้ำท่วมรถยนต์'!$DC:$DC,"") -> อนุมัติคืนทุน | O20: =_xlfn.XLOOKUP(K20,'[1]All เคลมน้ำท่วมรถยนต์'!$C:$C,'[1]All เคลมน้ำท่วมรถยนต์'!$DD:$DD,"") -> จ่ายแล้ว/ ยกเลิก | P20: =_xlfn.XLOOKUP(K20,'[1]All เคลมน้ำท่วมรถยนต์'!$C:$C,'[1]All เคลมน้ำท่วมรถยนต์'!$CA:$CA,"") -> ประเภท1 | Q20: =_xlfn.XLOOKUP(K20,'[1]All เคลมน้ำท่วมรถยนต์'!$C:$C,'[1]All เคลมน้ำท่วมรถยนต์'!$BX:$BX,"") -> 570000 | R20: =_xlfn.XLOOKUP(K20,'[1]All เคลมน้ำท่วมรถยนต์'!$C:$C,'[1]All เคลมน้ำท่วมรถยนต์'!$CB:$CB,"") -> 570000 | S20: =_xlfn.XLOOKUP(L20,[2]รายการรถยนต์!$H:$H,[2]รายการรถยนต์!$J:$J,"") | Z20: =_xlfn.XLOOKUP(K20,'[1]All เคลมน้ำท่วมรถยนต์'!$C:$C,'[1]All เคลมน้ำท่วมรถยนต์'!$CS:$CS,"") -> 570000 | AA20: =_xlfn.XLOOKUP(K20,'[1]All เคลมน้ำท่วมรถยนต์'!$C:$C,'[1]All เคลมน้ำท่วมรถยนต์'!$CT:$CT,"") -> 46021 | AB20: =_xlfn.XLOOKUP(K20,'[1]All เคลมน้ำท่วมรถยนต์'!$C:$C,'[1]All เคลมน้ำท่วมรถยนต์'!$CV:$CV,"") -> นาง วันดี เจริญศรี
A21: 20 | B21: 3กร-8990 | K21: 502-25-71-RMO-04058 | L21: 502-25-71-CMO-04019 | M21: =_xlfn.XLOOKUP(K21,'[1]All เคลมน้ำท่วมรถยนต์'!$C:$C,'[1]All เคลมน้ำท่วมรถยนต์'!$DC:$DC,"") | O21: =_xlfn.XLOOKUP(K21,'[1]All เคลมน้ำท่วมรถยนต์'!$C:$C,'[1]All เคลมน้ำท่วมรถยนต์'!$DD:$DD,"") -> อนุมัติคืนทุนแล้ว - ยังไม่ถึงพี่ใหม่ | P21: =_xlfn.XLOOKUP(K21,'[1]All เคลมน้ำท่วมรถยนต์'!$C:$C,'[1]All เคลมน้ำท่วมรถยนต์'!$CA:$CA,"") -> ประเภท2+ | Q21: =_xlfn.XLOOKUP(K21,'[1]All เคลมน้ำท่วมรถยนต์'!$C:$C,'[1]All เคลมน้ำท่วมรถยนต์'!$BX:$BX,"") -> 300000 | R21: =_xlfn.XLOOKUP(K21,'[1]All เคลมน้ำท่วมรถยนต์'!$C:$C,'[1]All เคลมน้ำท่วมรถยนต์'!$CB:$CB,"") -> 50000 | S21: =_xlfn.XLOOKUP(L21,[2]รายการรถยนต์!$H:$H,[2]รายการรถยนต์!$J:$J,"") | Z21: =_xlfn.XLOOKUP(K21,'[1]All เคลมน้ำท่วมรถยนต์'!$C:$C,'[1]All เคลมน้ำท่วมรถยนต์'!$CS:$CS,"") -> 0 | AA21: =_xlfn.XLOOKUP(K21,'[1]All เคลมน้ำท่วมรถยนต์'!$C:$C,'[1]All เคลมน้ำท่วมรถยนต์'!$CT:$CT,"") | AB21: =_xlfn.XLOOKUP(K21,'[1]All เคลมน้ำท่วมรถยนต์'!$C:$C,'[1]All เคลมน้ำท่วมรถยนต์'!$CV:$CV,"") -> 0
A22: 21 | B22: ผจ-1583 | C22: สุราษฎร์ธานี | D22: TOYOTA | E22: Revo | F22: ขาว | G22: 46045 | H22: ย้ายลาน | I22: ลาน1-ช่องเขา | J22: ลาน8-ไฟร์มเครสต์ | K22: 502-25-71-RMO-04059 | L22: 502-25-71-CMO-04034 | M22: =_xlfn.XLOOKUP(K22,'[1]All เคลมน้ำท่วมรถยนต์'!$C:$C,'[1]All เคลมน้ำท่วมรถยนต์'!$DC:$DC,"") -> อนุมัติคืนทุน | O22: =_xlfn.XLOOKUP(K22,'[1]All เคลมน้ำท่วมรถยนต์'!$C:$C,'[1]All เคลมน้ำท่วมรถยนต์'!$DD:$DD,"") -> จ่ายแล้ว/ ยกเลิก | P22: =_xlfn.XLOOKUP(K22,'[1]All เคลมน้ำท่วมรถยนต์'!$C:$C,'[1]All เคลมน้ำท่วมรถยนต์'!$CA:$CA,"") -> ประเภท1 | Q22: =_xlfn.XLOOKUP(K22,'[1]All เคลมน้ำท่วมรถยนต์'!$C:$C,'[1]All เคลมน้ำท่วมรถยนต์'!$BX:$BX,"") -> 240000 | R22: =_xlfn.XLOOKUP(K22,'[1]All เคลมน้ำท่วมรถยนต์'!$C:$C,'[1]All เคลมน้ำท่วมรถยนต์'!$CB:$CB,"") -> 240000 | S22: =_xlfn.XLOOKUP(L22,[2]รายการรถยนต์!$H:$H,[2]รายการรถยนต์!$J:$J,"") -> 91200 | Z22: =_xlfn.XLOOKUP(K22,'[1]All เคลมน้ำท่วมรถยนต์'!$C:$C,'[1]All เคลมน้ำท่วมรถยนต์'!$CS:$CS,"") -> 240000 | AA22: =_xlfn.XLOOKUP(K22,'[1]All เคลมน้ำท่วมรถยนต์'!$C:$C,'[1]All เคลมน้ำท่วมรถยนต์'!$CT:$CT,"") -> 46037 | AB22: =_xlfn.XLOOKUP(K22,'[1]All เคลมน้ำท่วมรถยนต์'!$C:$C,'[1]All เคลมน้ำท่วมรถยนต์'!$CV:$CV,"") -> บริษัท เอสแอลเอส ทรานสปอร์ต แอนด์ โลจิสติกส์ จำกัด
A23: 22 | B23: ขว-248 | C23: สงขลา | D23: MAZDA | E23: 2 | F23: ดำ | G23: 46045 | H23: ย้ายลาน | I23: ลาน6 | J23: ลาน8-ไฟร์มเครสต์ | K23: 502-25-71-RMO-04060 | L23: 502-25-71-CMO-04015 | M23: =_xlfn.XLOOKUP(K23,'[1]All เคลมน้ำท่วมรถยนต์'!$C:$C,'[1]All เคลมน้ำท่วมรถยนต์'!$DC:$DC,"") | O23: =_xlfn.XLOOKUP(K23,'[1]All เคลมน้ำท่วมรถยนต์'!$C:$C,'[1]All เคลมน้ำท่วมรถยนต์'!$DD:$DD,"") -> มีประมาณการเบื้องต้นแล้ว ยังไม่เปิด GP/อนุมัติจ่าย | P23: =_xlfn.XLOOKUP(K23,'[1]All เคลมน้ำท่วมรถยนต์'!$C:$C,'[1]All เคลมน้ำท่วมรถยนต์'!$CA:$CA,"") -> ประเภท1 | Q23: =_xlfn.XLOOKUP(K23,'[1]All เคลมน้ำท่วมรถยนต์'!$C:$C,'[1]All เคลมน้ำท่วมรถยนต์'!$BX:$BX,"") -> 270000 | R23: =_xlfn.XLOOKUP(K23,'[1]All เคลมน้ำท่วมรถยนต์'!$C:$C,'[1]All เคลมน้ำท่วมรถยนต์'!$CB:$CB,"") -> 270000 | S23: =_xlfn.XLOOKUP(L23,[2]รายการรถยนต์!$H:$H,[2]รายการรถยนต์!$J:$J,"") -> 102600 | Z23: =_xlfn.XLOOKUP(K23,'[1]All เคลมน้ำท่วมรถยนต์'!$C:$C,'[1]All เคลมน้ำท่วมรถยนต์'!$CS:$CS,"") -> 0 | AA23: =_xlfn.XLOOKUP(K23,'[1]All เคลมน้ำท่วมรถยนต์'!$C:$C,'[1]All เคลมน้ำท่วมรถยนต์'!$CT:$CT,"") | AB23: =_xlfn.XLOOKUP(K23,'[1]All เคลมน้ำท่วมรถยนต์'!$C:$C,'[1]All เคลมน้ำท่วมรถยนต์'!$CV:$CV,"") -> 0
A24: 23 | B24: ขน-2967 | C24: สงขลา | D24: MITSUBISHI | E24: MIRAGE | G24: 46045 | H24: ย้ายลาน | I24: ลาน2-ท่าช้าง(ดินถล่ม) | J24: ลาน8-ไฟร์มเครสต์ | K24: 502-25-71-RMO-04061 | L24: 502-25-71-CMO-04013 | M24: =_xlfn.XLOOKUP(K24,'[1]All เคลมน้ำท่วมรถยนต์'!$C:$C,'[1]All เคลมน้ำท่วมรถยนต์'!$DC:$DC,"") -> อนุมัติคืนทุน | O24: =_xlfn.XLOOKUP(K24,'[1]All เคลมน้ำท่วมรถยนต์'!$C:$C,'[1]All เคลมน้ำท่วมรถยนต์'!$DD:$DD,"") -> จ่ายแล้ว/ ยกเลิก | P24: =_xlfn.XLOOKUP(K24,'[1]All เคลมน้ำท่วมรถยนต์'!$C:$C,'[1]All เคลมน้ำท่วมรถยนต์'!$CA:$CA,"") -> ประเภท1 | Q24: =_xlfn.XLOOKUP(K24,'[1]All เคลมน้ำท่วมรถยนต์'!$C:$C,'[1]All เคลมน้ำท่วมรถยนต์'!$BX:$BX,"") -> 170000 | R24: =_xlfn.XLOOKUP(K24,'[1]All เคลมน้ำท่วมรถยนต์'!$C:$C,'[1]All เคลมน้ำท่วมรถยนต์'!$CB:$CB,"") -> 170000 | S24: =_xlfn.XLOOKUP(L24,[2]รายการรถยนต์!$H:$H,[2]รายการรถยนต์!$J:$J,"") -> 64600 | Z24: =_xlfn.XLOOKUP(K24,'[1]All เคลมน้ำท่วมรถยนต์'!$C:$C,'[1]All เคลมน้ำท่วมรถยนต์'!$CS:$CS,"") -> 170000 | AA24: =_xlfn.XLOOKUP(K24,'[1]All เคลมน้ำท่วมรถยนต์'!$C:$C,'[1]All เคลมน้ำท่วมรถยนต์'!$CT:$CT,"") -> 46021 | AB24: =_xlfn.XLOOKUP(K24,'[1]All เคลมน้ำท่วมรถยนต์'!$C:$C,'[1]All เคลมน้ำท่วมรถยนต์'!$CV:$CV,"") -> คุณ ขนิษฐา ตั้งสถิตวรรณ
A25: 24 | B25: งบ-2812 | H25: ซ่อม | K25: 502-25-71-RMO-04062 | L25: 502-25-71-CMO-03995 | M25: =_xlfn.XLOOKUP(K25,'[1]All เคลมน้ำท่วมรถยนต์'!$C:$C,'[1]All เคลมน้ำท่วมรถยนต์'!$DC:$DC,"") -> เข้าซ่อม | O25: =_xlfn.XLOOKUP(K25,'[1]All เคลมน้ำท่วมรถยนต์'!$C:$C,'[1]All เคลมน้ำท่วมรถยนต์'!$DD:$DD,"") -> เข้าซ่อม | P25: =_xlfn.XLOOKUP(K25,'[1]All เคลมน้ำท่วมรถยนต์'!$C:$C,'[1]All เคลมน้ำท่วมรถยนต์'!$CA:$CA,"") -> ประเภท1 | Q25: =_xlfn.XLOOKUP(K25,'[1]All เคลมน้ำท่วมรถยนต์'!$C:$C,'[1]All เคลมน้ำท่วมรถยนต์'!$BX:$BX,"") -> 400000 | R25: =_xlfn.XLOOKUP(K25,'[1]All เคลมน้ำท่วมรถยนต์'!$C:$C,'[1]All เคลมน้ำท่วมรถยนต์'!$CB:$CB,"") -> 30000 | S25: =_xlfn.XLOOKUP(L25,[2]รายการรถยนต์!$H:$H,[2]รายการรถยนต์!$J:$J,"") | Z25: =_xlfn.XLOOKUP(K25,'[1]All เคลมน้ำท่วมรถยนต์'!$C:$C,'[1]All เคลมน้ำท่วมรถยนต์'!$CS:$CS,"") -> 0 | AA25: =_xlfn.XLOOKUP(K25,'[1]All เคลมน้ำท่วมรถยนต์'!$C:$C,'[1]All เคลมน้ำท่วมรถยนต์'!$CT:$CT,"") | AB25: =_xlfn.XLOOKUP(K25,'[1]All เคลมน้ำท่วมรถยนต์'!$C:$C,'[1]All เคลมน้ำท่วมรถยนต์'!$CV:$CV,"") -> 0
A26: 25 | B26: กง-2544 | C26: สตูลูล | D26: HONDA | E26: City | G26: 46045 | H26: ย้ายลาน | I26: ลาน2-ท่าช้าง(ดินถล่ม) | J26: ลาน8-ไฟร์มเครสต์ | K26: 502-25-71-RMO-04064 | L26: 502-25-71-CMO-04014 | M26: =_xlfn.XLOOKUP(K26,'[1]All เคลมน้ำท่วมรถยนต์'!$C:$C,'[1]All เคลมน้ำท่วมรถยนต์'!$DC:$DC,"") -> อนุมัติคืนทุน | O26: =_xlfn.XLOOKUP(K26,'[1]All เคลมน้ำท่วมรถยนต์'!$C:$C,'[1]All เคลมน้ำท่วมรถยนต์'!$DD:$DD,"") -> จ่ายแล้ว/ ยกเลิก | P26: =_xlfn.XLOOKUP(K26,'[1]All เคลมน้ำท่วมรถยนต์'!$C:$C,'[1]All เคลมน้ำท่วมรถยนต์'!$CA:$CA,"") -> ประเภท1 | Q26: =_xlfn.XLOOKUP(K26,'[1]All เคลมน้ำท่วมรถยนต์'!$C:$C,'[1]All เคลมน้ำท่วมรถยนต์'!$BX:$BX,"") -> 300000 | R26: =_xlfn.XLOOKUP(K26,'[1]All เคลมน้ำท่วมรถยนต์'!$C:$C,'[1]All เคลมน้ำท่วมรถยนต์'!$CB:$CB,"") -> 300000 | S26: =_xlfn.XLOOKUP(L26,[2]รายการรถยนต์!$H:$H,[2]รายการรถยนต์!$J:$J,"") -> 114000 | Z26: =_xlfn.XLOOKUP(K26,'[1]All เคลมน้ำท่วมรถยนต์'!$C:$C,'[1]All เคลมน้ำท่วมรถยนต์'!$CS:$CS,"") -> 300000 | AA26: =_xlfn.XLOOKUP(K26,'[1]All เคลมน้ำท่วมรถยนต์'!$C:$C,'[1]All เคลมน้ำท่วมรถยนต์'!$CT:$CT,"") -> 46021 | AB26: =_xlfn.XLOOKUP(K26,'[1]All เคลมน้ำท่วมรถยนต์'!$C:$C,'[1]All เคลมน้ำท่วมรถยนต์'!$CV:$CV,"") -> คุณ ธีรณุ ไกรวงศ์
A27: 26 | B27: กย-8938 | C27: สงขลา | D27: ISUZU | E27: D-MAX | F27: เทา | G27: 46045 | H27: ย้ายลาน | I27: ลาน3-สะพานสูงเทคโน(Motto) | J27: ลาน8-ไฟร์มเครสต์ | K27: 502-25-71-RMO-04065 | L27: 502-25-71-CMO-04016 | M27: =_xlfn.XLOOKUP(K27,'[1]All เคลมน้ำท่วมรถยนต์'!$C:$C,'[1]All เคลมน้ำท่วมรถยนต์'!$DC:$DC,"") -> อนุมัติคืนทุน | O27: =_xlfn.XLOOKUP(K27,'[1]All เคลมน้ำท่วมรถยนต์'!$C:$C,'[1]All เคลมน้ำท่วมรถยนต์'!$DD:$DD,"") -> จ่ายแล้ว/ ยกเลิก | P27: =_xlfn.XLOOKUP(K27,'[1]All เคลมน้ำท่วมรถยนต์'!$C:$C,'[1]All เคลมน้ำท่วมรถยนต์'!$CA:$CA,"") -> ประเภท1 | Q27: =_xlfn.XLOOKUP(K27,'[1]All เคลมน้ำท่วมรถยนต์'!$C:$C,'[1]All เคลมน้ำท่วมรถยนต์'!$BX:$BX,"") -> 140000 | R27: =_xlfn.XLOOKUP(K27,'[1]All เคลมน้ำท่วมรถยนต์'!$C:$C,'[1]All เคลมน้ำท่วมรถยนต์'!$CB:$CB,"") -> 140000 | S27: =_xlfn.XLOOKUP(L27,[2]รายการรถยนต์!$H:$H,[2]รายการรถยนต์!$J:$J,"") -> 53200 | Z27: =_xlfn.XLOOKUP(K27,'[1]All เคลมน้ำท่วมรถยนต์'!$C:$C,'[1]All เคลมน้ำท่วมรถยนต์'!$CS:$CS,"") -> 140000 | AA27: =_xlfn.XLOOKUP(K27,'[1]All เคลมน้ำท่วมรถยนต์'!$C:$C,'[1]All เคลมน้ำท่วมรถยนต์'!$CT:$CT,"") -> 45992 | AB27: =_xlfn.XLOOKUP(K27,'[1]All เคลมน้ำท่วมรถยนต์'!$C:$C,'[1]All เคลมน้ำท่วมรถยนต์'!$CV:$CV,"") -> นาง กุสุมา เจ๊ะเต๊ะ
A28: 27 | B28: ขต-4548 | C28: สงขลา | D28: TOYOTA | E28: COROLLA | K28: 502-25-71-RMO-04066 | L28: 502-25-71-CMO-03996 | M28: =_xlfn.XLOOKUP(K28,'[1]All เคลมน้ำท่วมรถยนต์'!$C:$C,'[1]All เคลมน้ำท่วมรถยนต์'!$DC:$DC,"") -> อนุมัติคืนทุน | O28: =_xlfn.XLOOKUP(K28,'[1]All เคลมน้ำท่วมรถยนต์'!$C:$C,'[1]All เคลมน้ำท่วมรถยนต์'!$DD:$DD,"") -> จ่ายแล้ว/ ยกเลิก | P28: =_xlfn.XLOOKUP(K28,'[1]All เคลมน้ำท่วมรถยนต์'!$C:$C,'[1]All เคลมน้ำท่วมรถยนต์'!$CA:$CA,"") -> ประเภท1 | Q28: =_xlfn.XLOOKUP(K28,'[1]All เคลมน้ำท่วมรถยนต์'!$C:$C,'[1]All เคลมน้ำท่วมรถยนต์'!$BX:$BX,"") -> 270000 | R28: =_xlfn.XLOOKUP(K28,'[1]All เคลมน้ำท่วมรถยนต์'!$C:$C,'[1]All เคลมน้ำท่วมรถยนต์'!$CB:$CB,"") -> 270000 | S28: =_xlfn.XLOOKUP(L28,[2]รายการรถยนต์!$H:$H,[2]รายการรถยนต์!$J:$J,"") | Z28: =_xlfn.XLOOKUP(K28,'[1]All เคลมน้ำท่วมรถยนต์'!$C:$C,'[1]All เคลมน้ำท่วมรถยนต์'!$CS:$CS,"") -> 270000 | AA28: =_xlfn.XLOOKUP(K28,'[1]All เคลมน้ำท่วมรถยนต์'!$C:$C,'[1]All เคลมน้ำท่วมรถยนต์'!$CT:$CT,"") -> 46043 | AB28: =_xlfn.XLOOKUP(K28,'[1]All เคลมน้ำท่วมรถยนต์'!$C:$C,'[1]All เคลมน้ำท่วมรถยนต์'!$CV:$CV,"") -> นางสาว นัยนา บุญทรง
A29: 28 | B29: ขท-3571 | C29: สงขลา | D29: TOYOTA | E29: COROLLA | K29: 502-25-71-RMO-04067 | L29: 502-25-71-CMO-03999 | M29: =_xlfn.XLOOKUP(K29,'[1]All เคลมน้ำท่วมรถยนต์'!$C:$C,'[1]All เคลมน้ำท่วมรถยนต์'!$DC:$DC,"") | O29: =_xlfn.XLOOKUP(K29,'[1]All เคลมน้ำท่วมรถยนต์'!$C:$C,'[1]All เคลมน้ำท่วมรถยนต์'!$DD:$DD,"") -> จ่ายแล้ว/ ยกเลิก | P29: =_xlfn.XLOOKUP(K29,'[1]All เคลมน้ำท่วมรถยนต์'!$C:$C,'[1]All เคลมน้ำท่วมรถยนต์'!$CA:$CA,"") -> ประเภท2+ | Q29: =_xlfn.XLOOKUP(K29,'[1]All เคลมน้ำท่วมรถยนต์'!$C:$C,'[1]All เคลมน้ำท่วมรถยนต์'!$BX:$BX,"") -> 300000 | R29: =_xlfn.XLOOKUP(K29,'[1]All เคลมน้ำท่วมรถยนต์'!$C:$C,'[1]All เคลมน้ำท่วมรถยนต์'!$CB:$CB,"") -> 50000 | S29: =_xlfn.XLOOKUP(L29,[2]รายการรถยนต์!$H:$H,[2]รายการรถยนต์!$J:$J,"") | Z29: =_xlfn.XLOOKUP(K29,'[1]All เคลมน้ำท่วมรถยนต์'!$C:$C,'[1]All เคลมน้ำท่วมรถยนต์'!$CS:$CS,"") -> 50000 | AA29: =_xlfn.XLOOKUP(K29,'[1]All เคลมน้ำท่วมรถยนต์'!$C:$C,'[1]All เคลมน้ำท่วมรถยนต์'!$CT:$CT,"") -> 46030 | AB29: =_xlfn.XLOOKUP(K29,'[1]All เคลมน้ำท่วมรถยนต์'!$C:$C,'[1]All เคลมน้ำท่วมรถยนต์'!$CV:$CV,"") -> นาง สาวิตรี วัฒนวาที
A30: 29 | B30: ขต-4128 | C30: สงขลา | D30: TOYOTA | E30: Vios | F30: ขาว | G30: 46045 | H30: ย้ายลาน | I30: ลาน6 | J30: ลาน8-ไฟร์มเครสต์ | K30: 502-25-71-RMO-04068 | L30: 502-25-71-CMO-03997 | M30: =_xlfn.XLOOKUP(K30,'[1]All เคลมน้ำท่วมรถยนต์'!$C:$C,'[1]All เคลมน้ำท่วมรถยนต์'!$DC:$DC,"") -> อนุมัติคืนทุน | O30: =_xlfn.XLOOKUP(K30,'[1]All เคลมน้ำท่วมรถยนต์'!$C:$C,'[1]All เคลมน้ำท่วมรถยนต์'!$DD:$DD,"") -> จ่ายแล้ว/ ยกเลิก | P30: =_xlfn.XLOOKUP(K30,'[1]All เคลมน้ำท่วมรถยนต์'!$C:$C,'[1]All เคลมน้ำท่วมรถยนต์'!$CA:$CA,"") -> ประเภท1 | Q30: =_xlfn.XLOOKUP(K30,'[1]All เคลมน้ำท่วมรถยนต์'!$C:$C,'[1]All เคลมน้ำท่วมรถยนต์'!$BX:$BX,"") -> 210000 | R30: =_xlfn.XLOOKUP(K30,'[1]All เคลมน้ำท่วมรถยนต์'!$C:$C,'[1]All เคลมน้ำท่วมรถยนต์'!$CB:$CB,"") -> 210000 | S30: =_xlfn.XLOOKUP(L30,[2]รายการรถยนต์!$H:$H,[2]รายการรถยนต์!$J:$J,"") -> 79800 | Z30: =_xlfn.XLOOKUP(K30,'[1]All เคลมน้ำท่วมรถยนต์'!$C:$C,'[1]All เคลมน้ำท่วมรถยนต์'!$CS:$CS,"") -> 210000 | AA30: =_xlfn.XLOOKUP(K30,'[1]All เคลมน้ำท่วมรถยนต์'!$C:$C,'[1]All เคลมน้ำท่วมรถยนต์'!$CT:$CT,"") -> 46021 | AB30: =_xlfn.XLOOKUP(K30,'[1]All เคลมน้ำท่วมรถยนต์'!$C:$C,'[1]All เคลมน้ำท่วมรถยนต์'!$CV:$CV,"") -> นาย ปรีดา พรหมสุวรรณ์
A31: 30 | B31: 6กร-7933 | F31: เทาบรอนซ์ | G31: 46002.411 | I31: ลาน1-ช่องเขา | K31: 502-25-71-RMO-04070 | L31: 502-25-71-CMO-04000 | M31: =_xlfn.XLOOKUP(K31,'[1]All เคลมน้ำท่วมรถยนต์'!$C:$C,'[1]All เคลมน้ำท่วมรถยนต์'!$DC:$DC,"") -> รออนุมัติ | O31: =_xlfn.XLOOKUP(K31,'[1]All เคลมน้ำท่วมรถยนต์'!$C:$C,'[1]All เคลมน้ำท่วมรถยนต์'!$DD:$DD,"") -> เข้าซ่อม | P31: =_xlfn.XLOOKUP(K31,'[1]All เคลมน้ำท่วมรถยนต์'!$C:$C,'[1]All เคลมน้ำท่วมรถยนต์'!$CA:$CA,"") -> ประเภท1 | Q31: =_xlfn.XLOOKUP(K31,'[1]All เคลมน้ำท่วมรถยนต์'!$C:$C,'[1]All เคลมน้ำท่วมรถยนต์'!$BX:$BX,"") -> 270000 | R31: =_xlfn.XLOOKUP(K31,'[1]All เคลมน้ำท่วมรถยนต์'!$C:$C,'[1]All เคลมน้ำท่วมรถยนต์'!$CB:$CB,"") -> 150000 | S31: =_xlfn.XLOOKUP(L31,[2]รายการรถยนต์!$H:$H,[2]รายการรถยนต์!$J:$J,"") | Z31: =_xlfn.XLOOKUP(K31,'[1]All เคลมน้ำท่วมรถยนต์'!$C:$C,'[1]All เคลมน้ำท่วมรถยนต์'!$CS:$CS,"") -> 0 | AA31: =_xlfn.XLOOKUP(K31,'[1]All เคลมน้ำท่วมรถยนต์'!$C:$C,'[1]All เคลมน้ำท่วมรถยนต์'!$CT:$CT,"") | AB31: =_xlfn.XLOOKUP(K31,'[1]All เคลมน้ำท่วมรถยนต์'!$C:$C,'[1]All เคลมน้ำท่วมรถยนต์'!$CV:$CV,"") -> 0
A32: 31 | B32: กค-5148 | C32: สตูล | D32: FORD | E32: FIESTA | G32: 46045 | H32: ย้ายลาน | I32: ลาน2-ท่าช้าง(ดินถล่ม) | J32: ลาน8-ไฟร์มเครสต์ | K32: 502-25-71-RMO-04071 | L32: 502-25-71-CMO-03981 | M32: =_xlfn.XLOOKUP(K32,'[1]All เคลมน้ำท่วมรถยนต์'!$C:$C,'[1]All เคลมน้ำท่วมรถยนต์'!$DC:$DC,"") -> อนุมัติคืนทุน | O32: =_xlfn.XLOOKUP(K32,'[1]All เคลมน้ำท่วมรถยนต์'!$C:$C,'[1]All เคลมน้ำท่วมรถยนต์'!$DD:$DD,"") -> จ่ายแล้ว/ ยกเลิก | P32: =_xlfn.XLOOKUP(K32,'[1]All เคลมน้ำท่วมรถยนต์'!$C:$C,'[1]All เคลมน้ำท่วมรถยนต์'!$CA:$CA,"") -> ประเภท1 | Q32: =_xlfn.XLOOKUP(K32,'[1]All เคลมน้ำท่วมรถยนต์'!$C:$C,'[1]All เคลมน้ำท่วมรถยนต์'!$BX:$BX,"") -> 150000 | R32: =_xlfn.XLOOKUP(K32,'[1]All เคลมน้ำท่วมรถยนต์'!$C:$C,'[1]All เคลมน้ำท่วมรถยนต์'!$CB:$CB,"") -> 150000 | S32: =_xlfn.XLOOKUP(L32,[2]รายการรถยนต์!$H:$H,[2]รายการรถยนต์!$J:$J,"") -> 57000 | Z32: =_xlfn.XLOOKUP(K32,'[1]All เคลมน้ำท่วมรถยนต์'!$C:$C,'[1]All เคลมน้ำท่วมรถยนต์'!$CS:$CS,"") -> 150000 | AA32: =_xlfn.XLOOKUP(K32,'[1]All เคลมน้ำท่วมรถยนต์'!$C:$C,'[1]All เคลมน้ำท่วมรถยนต์'!$CT:$CT,"") -> 46021 | AB32: =_xlfn.XLOOKUP(K32,'[1]All เคลมน้ำท่วมรถยนต์'!$C:$C,'[1]All เคลมน้ำท่วมรถยนต์'!$CV:$CV,"") -> นาย สิตางศุ์ ชวนานันท์
A33: 32 | B33: 1ขข-3219 | H33: ซ่อม | K33: 502-25-71-RMO-04072 | L33: 502-25-71-CMO-04001 | M33: =_xlfn.XLOOKUP(K33,'[1]All เคลมน้ำท่วมรถยนต์'!$C:$C,'[1]All เคลมน้ำท่วมรถยนต์'!$DC:$DC,"") -> เข้าซ่อม | O33: =_xlfn.XLOOKUP(K33,'[1]All เคลมน้ำท่วมรถยนต์'!$C:$C,'[1]All เคลมน้ำท่วมรถยนต์'!$DD:$DD,"") -> จ่ายแล้ว/ ยกเลิก | P33: =_xlfn.XLOOKUP(K33,'[1]All เคลมน้ำท่วมรถยนต์'!$C:$C,'[1]All เคลมน้ำท่วมรถยนต์'!$CA:$CA,"") -> ประเภท1 | Q33: =_xlfn.XLOOKUP(K33,'[1]All เคลมน้ำท่วมรถยนต์'!$C:$C,'[1]All เคลมน้ำท่วมรถยนต์'!$BX:$BX,"") -> 450000 | R33: =_xlfn.XLOOKUP(K33,'[1]All เคลมน้ำท่วมรถยนต์'!$C:$C,'[1]All เคลมน้ำท่วมรถยนต์'!$CB:$CB,"") -> 10000 | S33: =_xlfn.XLOOKUP(L33,[2]รายการรถยนต์!$H:$H,[2]รายการรถยนต์!$J:$J,"") | Z33: =_xlfn.XLOOKUP(K33,'[1]All เคลมน้ำท่วมรถยนต์'!$C:$C,'[1]All เคลมน้ำท่วมรถยนต์'!$CS:$CS,"") -> 9400 | AA33: =_xlfn.XLOOKUP(K33,'[1]All เคลมน้ำท่วมรถยนต์'!$C:$C,'[1]All เคลมน้ำท่วมรถยนต์'!$CT:$CT,"") -> 46029 | AB33: =_xlfn.XLOOKUP(K33,'[1]All เคลมน้ำท่วมรถยนต์'!$C:$C,'[1]All เคลมน้ำท่วมรถยนต์'!$CV:$CV,"") -> นาย ปารมี ขุนศรีรักษา
A34: 33 | B34: ขต-6135 | C34: สงขลา | D34: CHEVROLET | E34: SONIC | K34: 502-25-71-RMO-04073 | L34: 502-25-71-CMO-03998 | M34: =_xlfn.XLOOKUP(K34,'[1]All เคลมน้ำท่วมรถยนต์'!$C:$C,'[1]All เคลมน้ำท่วมรถยนต์'!$DC:$DC,"") | O34: =_xlfn.XLOOKUP(K34,'[1]All เคลมน้ำท่วมรถยนต์'!$C:$C,'[1]All เคลมน้ำท่วมรถยนต์'!$DD:$DD,"") -> จ่ายแล้ว/ ยกเลิก | P34: =_xlfn.XLOOKUP(K34,'[1]All เคลมน้ำท่วมรถยนต์'!$C:$C,'[1]All เคลมน้ำท่วมรถยนต์'!$CA:$CA,"") -> ประเภท2+ | Q34: =_xlfn.XLOOKUP(K34,'[1]All เคลมน้ำท่วมรถยนต์'!$C:$C,'[1]All เคลมน้ำท่วมรถยนต์'!$BX:$BX,"") -> 100000 | R34: =_xlfn.XLOOKUP(K34,'[1]All เคลมน้ำท่วมรถยนต์'!$C:$C,'[1]All เคลมน้ำท่วมรถยนต์'!$CB:$CB,"") -> 0 ไม่คุ้มครองภัยน้ำท่วม | S34: =_xlfn.XLOOKUP(L34,[2]รายการรถยนต์!$H:$H,[2]รายการรถยนต์!$J:$J,"") | Z34: =_xlfn.XLOOKUP(K34,'[1]All เคลมน้ำท่วมรถยนต์'!$C:$C,'[1]All เคลมน้ำท่วมรถยนต์'!$CS:$CS,"") -> 0 | AA34: =_xlfn.XLOOKUP(K34,'[1]All เคลมน้ำท่วมรถยนต์'!$C:$C,'[1]All เคลมน้ำท่วมรถยนต์'!$CT:$CT,"") -> ยกเลิกเคลม | AB34: =_xlfn.XLOOKUP(K34,'[1]All เคลมน้ำท่วมรถยนต์'!$C:$C,'[1]All เคลมน้ำท่วมรถยนต์'!$CV:$CV,"") -> 0
A35: 34 | B35: กต-654 | C35: พัทลุง​ | D35: MG | E35: MG3 | F35: ชาว | G35: 46002.5 | I35: ลาน1-ช่องเขา | K35: 502-25-71-RMO-04075 | L35: 502-25-71-CMO-03983 | M35: =_xlfn.XLOOKUP(K35,'[1]All เคลมน้ำท่วมรถยนต์'!$C:$C,'[1]All เคลมน้ำท่วมรถยนต์'!$DC:$DC,"") | O35: =_xlfn.XLOOKUP(K35,'[1]All เคลมน้ำท่วมรถยนต์'!$C:$C,'[1]All เคลมน้ำท่วมรถยนต์'!$DD:$DD,"") -> จ่ายแล้ว/ ยกเลิก | P35: =_xlfn.XLOOKUP(K35,'[1]All เคลมน้ำท่วมรถยนต์'!$C:$C,'[1]All เคลมน้ำท่วมรถยนต์'!$CA:$CA,"") -> ประเภท2+ | Q35: =_xlfn.XLOOKUP(K35,'[1]All เคลมน้ำท่วมรถยนต์'!$C:$C,'[1]All เคลมน้ำท่วมรถยนต์'!$BX:$BX,"") -> 200000 | R35: =_xlfn.XLOOKUP(K35,'[1]All เคลมน้ำท่วมรถยนต์'!$C:$C,'[1]All เคลมน้ำท่วมรถยนต์'!$CB:$CB,"") -> 50000 | S35: =_xlfn.XLOOKUP(L35,[2]รายการรถยนต์!$H:$H,[2]รายการรถยนต์!$J:$J,"") | Z35: =_xlfn.XLOOKUP(K35,'[1]All เคลมน้ำท่วมรถยนต์'!$C:$C,'[1]All เคลมน้ำท่วมรถยนต์'!$CS:$CS,"") -> 50000 | AA35: =_xlfn.XLOOKUP(K35,'[1]All เคลมน้ำท่วมรถยนต์'!$C:$C,'[1]All เคลมน้ำท่วมรถยนต์'!$CT:$CT,"") -> 46009 | AB35: =_xlfn.XLOOKUP(K35,'[1]All เคลมน้ำท่วมรถยนต์'!$C:$C,'[1]All เคลมน้ำท่วมรถยนต์'!$CV:$CV,"") -> คุณ ทศธัญญ์ธร วลีรัตนวงศ์
A36: 35 | B36: ขพ-8030 | C36: สงขลา | D36: HONDA | E36: HR-V | K36: 502-25-71-RMO-04077 | L36: 502-25-71-CMO-04004 | M36: =_xlfn.XLOOKUP(K36,'[1]All เคลมน้ำท่วมรถยนต์'!$C:$C,'[1]All เคลมน้ำท่วมรถยนต์'!$DC:$DC,"") -> อนุมัติ | O36: =_xlfn.XLOOKUP(K36,'[1]All เคลมน้ำท่วมรถยนต์'!$C:$C,'[1]All เคลมน้ำท่วมรถยนต์'!$DD:$DD,"") -> จ่ายแล้ว/ ยกเลิก | P36: =_xlfn.XLOOKUP(K36,'[1]All เคลมน้ำท่วมรถยนต์'!$C:$C,'[1]All เคลมน้ำท่วมรถยนต์'!$CA:$CA,"") -> ประเภท1 | Q36: =_xlfn.XLOOKUP(K36,'[1]All เคลมน้ำท่วมรถยนต์'!$C:$C,'[1]All เคลมน้ำท่วมรถยนต์'!$BX:$BX,"") -> 400000 | R36: =_xlfn.XLOOKUP(K36,'[1]All เคลมน้ำท่วมรถยนต์'!$C:$C,'[1]All เคลมน้ำท่วมรถยนต์'!$CB:$CB,"") -> 400000 | S36: =_xlfn.XLOOKUP(L36,[2]รายการรถยนต์!$H:$H,[2]รายการรถยนต์!$J:$J,"") | Z36: =_xlfn.XLOOKUP(K36,'[1]All เคลมน้ำท่วมรถยนต์'!$C:$C,'[1]All เคลมน้ำท่วมรถยนต์'!$CS:$CS,"") -> 54815.63 | AA36: =_xlfn.XLOOKUP(K36,'[1]All เคลมน้ำท่วมรถยนต์'!$C:$C,'[1]All เคลมน้ำท่วมรถยนต์'!$CT:$CT,"") -> 46021 | AB36: =_xlfn.XLOOKUP(K36,'[1]All เคลมน้ำท่วมรถยนต์'!$C:$C,'[1]All เคลมน้ำท่วมรถยนต์'!$CV:$CV,"") -> นาง สุปราณี บุญธรรม
A37: 36 | B37: งพ-2365 | C37: สงขลา | D37: TOYOTA | E37: CAMRY | F37: ขาว | G37: 46045 | H37: ย้ายลาน | I37: ลาน3-สะพานสูงเทคโน(Motto) | J37: ลาน8-ไฟร์มเครสต์ | K37: 502-25-71-RMO-04078 | L37: 502-25-71-CMO-04002 | M37: =_xlfn.XLOOKUP(K37,'[1]All เคลมน้ำท่วมรถยนต์'!$C:$C,'[1]All เคลมน้ำท่วมรถยนต์'!$DC:$DC,"") -> อนุมัติคืนทุน | O37: =_xlfn.XLOOKUP(K37,'[1]All เคลมน้ำท่วมรถยนต์'!$C:$C,'[1]All เคลมน้ำท่วมรถยนต์'!$DD:$DD,"") -> รอจ่าย (อยู่ในมือพี่ใหม่แล้ว) | P37: =_xlfn.XLOOKUP(K37,'[1]All เคลมน้ำท่วมรถยนต์'!$C:$C,'[1]All เคลมน้ำท่วมรถยนต์'!$CA:$CA,"") -> ประเภท1 | Q37: =_xlfn.XLOOKUP(K37,'[1]All เคลมน้ำท่วมรถยนต์'!$C:$C,'[1]All เคลมน้ำท่วมรถยนต์'!$BX:$BX,"") -> 600000 | R37: =_xlfn.XLOOKUP(K37,'[1]All เคลมน้ำท่วมรถยนต์'!$C:$C,'[1]All เคลมน้ำท่วมรถยนต์'!$CB:$CB,"") -> 600000 | S37: =_xlfn.XLOOKUP(L37,[2]รายการรถยนต์!$H:$H,[2]รายการรถยนต์!$J:$J,"") -> 228000 | Z37: =_xlfn.XLOOKUP(K37,'[1]All เคลมน้ำท่วมรถยนต์'!$C:$C,'[1]All เคลมน้ำท่วมรถยนต์'!$CS:$CS,"") -> 600000 | AA37: =_xlfn.XLOOKUP(K37,'[1]All เคลมน้ำท่วมรถยนต์'!$C:$C,'[1]All เคลมน้ำท่วมรถยนต์'!$CT:$CT,"") | AB37: =_xlfn.XLOOKUP(K37,'[1]All เคลมน้ำท่วมรถยนต์'!$C:$C,'[1]All เคลมน้ำท่วมรถยนต์'!$CV:$CV,"") -> ธนาคาร กรุงศรีอยุธยา จำกัด(มหาชน
A38: 37 | B38: ผธ-3461 | C38: สงขลา | D38: TOYOTA | E38: HILUX VIGO | H38: ซ่อม | K38: 502-25-71-RMO-04079 | L38: 502-25-71-CMO-04006 | M38: =_xlfn.XLOOKUP(K38,'[1]All เคลมน้ำท่วมรถยนต์'!$C:$C,'[1]All เคลมน้ำท่วมรถยนต์'!$DC:$DC,"") -> เข้าซ่อม | O38: =_xlfn.XLOOKUP(K38,'[1]All เคลมน้ำท่วมรถยนต์'!$C:$C,'[1]All เคลมน้ำท่วมรถยนต์'!$DD:$DD,"") -> เข้าซ่อม | P38: =_xlfn.XLOOKUP(K38,'[1]All เคลมน้ำท่วมรถยนต์'!$C:$C,'[1]All เคลมน้ำท่วมรถยนต์'!$CA:$CA,"") -> ประเภท1 | Q38: =_xlfn.XLOOKUP(K38,'[1]All เคลมน้ำท่วมรถยนต์'!$C:$C,'[1]All เคลมน้ำท่วมรถยนต์'!$BX:$BX,"") -> 200000 | R38: =_xlfn.XLOOKUP(K38,'[1]All เคลมน้ำท่วมรถยนต์'!$C:$C,'[1]All เคลมน้ำท่วมรถยนต์'!$CB:$CB,"") -> 0 | S38: =_xlfn.XLOOKUP(L38,[2]รายการรถยนต์!$H:$H,[2]รายการรถยนต์!$J:$J,"") | Z38: =_xlfn.XLOOKUP(K38,'[1]All เคลมน้ำท่วมรถยนต์'!$C:$C,'[1]All เคลมน้ำท่วมรถยนต์'!$CS:$CS,"") -> 0 | AA38: =_xlfn.XLOOKUP(K38,'[1]All เคลมน้ำท่วมรถยนต์'!$C:$C,'[1]All เคลมน้ำท่วมรถยนต์'!$CT:$CT,"") | AB38: =_xlfn.XLOOKUP(K38,'[1]All เคลมน้ำท่วมรถยนต์'!$C:$C,'[1]All เคลมน้ำท่วมรถยนต์'!$CV:$CV,"") -> 0
A39: 38 | B39: ขร-4405 | C39: สงขลา | D39: TOYOTA | E39: Vigo | G39: 46045 | H39: ย้ายลาน | I39: ลาน3-สะพานสูงเทคโน(Motto) | J39: ลาน8-ไฟร์มเครสต์ | K39: 502-25-71-RMO-04080 | L39: 502-25-71-CMO-03985 | M39: =_xlfn.XLOOKUP(K39,'[1]All เคลมน้ำท่วมรถยนต์'!$C:$C,'[1]All เคลมน้ำท่วมรถยนต์'!$DC:$DC,"") -> อนุมัติคืนทุน | O39: =_xlfn.XLOOKUP(K39,'[1]All เคลมน้ำท่วมรถยนต์'!$C:$C,'[1]All เคลมน้ำท่วมรถยนต์'!$DD:$DD,"") -> จ่ายแล้ว/ ยกเลิก | P39: =_xlfn.XLOOKUP(K39,'[1]All เคลมน้ำท่วมรถยนต์'!$C:$C,'[1]All เคลมน้ำท่วมรถยนต์'!$CA:$CA,"") -> ประเภท1 | Q39: =_xlfn.XLOOKUP(K39,'[1]All เคลมน้ำท่วมรถยนต์'!$C:$C,'[1]All เคลมน้ำท่วมรถยนต์'!$BX:$BX,"") -> 210000 | R39: =_xlfn.XLOOKUP(K39,'[1]All เคลมน้ำท่วมรถยนต์'!$C:$C,'[1]All เคลมน้ำท่วมรถยนต์'!$CB:$CB,"") -> 210000 | S39: =_xlfn.XLOOKUP(L39,[2]รายการรถยนต์!$H:$H,[2]รายการรถยนต์!$J:$J,"") -> 79800 | Z39: =_xlfn.XLOOKUP(K39,'[1]All เคลมน้ำท่วมรถยนต์'!$C:$C,'[1]All เคลมน้ำท่วมรถยนต์'!$CS:$CS,"") -> 210000 | AA39: =_xlfn.XLOOKUP(K39,'[1]All เคลมน้ำท่วมรถยนต์'!$C:$C,'[1]All เคลมน้ำท่วมรถยนต์'!$CT:$CT,"") -> 46029 | AB39: =_xlfn.XLOOKUP(K39,'[1]All เคลมน้ำท่วมรถยนต์'!$C:$C,'[1]All เคลมน้ำท่วมรถยนต์'!$CV:$CV,"") -> นางสาว กาญจนา จันทโร
A40: 39 | B40: 7กย-8771 | H40: ซ่อม | K40: 502-25-71-RMO-04082 | L40: 502-25-71-CMO-03986 | M40: =_xlfn.XLOOKUP(K40,'[1]All เคลมน้ำท่วมรถยนต์'!$C:$C,'[1]All เคลมน้ำท่วมรถยนต์'!$DC:$DC,"") -> เข้าซ่อม | O40: =_xlfn.XLOOKUP(K40,'[1]All เคลมน้ำท่วมรถยนต์'!$C:$C,'[1]All เคลมน้ำท่วมรถยนต์'!$DD:$DD,"") -> เข้าซ่อม | P40: =_xlfn.XLOOKUP(K40,'[1]All เคลมน้ำท่วมรถยนต์'!$C:$C,'[1]All เคลมน้ำท่วมรถยนต์'!$CA:$CA,"") -> ประเภท1 | Q40: =_xlfn.XLOOKUP(K40,'[1]All เคลมน้ำท่วมรถยนต์'!$C:$C,'[1]All เคลมน้ำท่วมรถยนต์'!$BX:$BX,"") -> 530000 | R40: =_xlfn.XLOOKUP(K40,'[1]All เคลมน้ำท่วมรถยนต์'!$C:$C,'[1]All เคลมน้ำท่วมรถยนต์'!$CB:$CB,"") -> 11649 | S40: =_xlfn.XLOOKUP(L40,[2]รายการรถยนต์!$H:$H,[2]รายการรถยนต์!$J:$J,"") | Z40: =_xlfn.XLOOKUP(K40,'[1]All เคลมน้ำท่วมรถยนต์'!$C:$C,'[1]All เคลมน้ำท่วมรถยนต์'!$CS:$CS,"") -> 0 | AA40: =_xlfn.XLOOKUP(K40,'[1]All เคลมน้ำท่วมรถยนต์'!$C:$C,'[1]All เคลมน้ำท่วมรถยนต์'!$CT:$CT,"") | AB40: =_xlfn.XLOOKUP(K40,'[1]All เคลมน้ำท่วมรถยนต์'!$C:$C,'[1]All เคลมน้ำท่วมรถยนต์'!$CV:$CV,"") -> 0
...

Sheet Sheet2
A1: เข้าใหม่ | B1: ส่งเข้าลานประมูล
A2: ย้ายลาน | B2: อนุมัติขายซาก
A3: ขายออก | B3: รับโอนเงินค่าซาก
